<?xml version="1.0"?>
<robot name="popat">

  <material name="green">
    <color rgba="0.0 0.5 0.0 1.0" />
  </material>
  <material name="blue">
    <color rgba="0.0 0.0 0.5 1.0" />
  </material>
  <material name="grey">
    <color rgba="0.5 0.5 0.5 1.0" />
  </material>

  <link name="base_link">
    <visual>
      <geometry>
        <box size="0.6 0.4 0.2" />
      </geometry>
      <origin xyz="0 0 0.1" rpy="0 0 0">
      </origin>
      <material name="green" />
    </visual>
  </link>

  <joint name="base_to_base_footprint" type="fixed">
    <parent link="base_link" />
    <child link="base_footprint" />
    <origin xyz="0 0 -0.1" rpy="0 0 0" />
  </joint>

  <link name="base_footprint">

  </link>

  <joint name="base_to_right_wheel" type="continuous">
    <parent link="base_link" />
    <child link="right_wheel_link" />
    <origin xyz="-0.15 -0.225 0" rpy="1.57 0 0" />
    <axis xyz="0 0 1" />
  </joint>

  <link name="right_wheel_link">
    <visual>
      <geometry>
        <cylinder length="0.05" radius="0.1" />
      </geometry>
      <origin xyz="0 0 0" rpy="0 0 0">
      </origin>
      <material name="grey" />
    </visual>
  </link>

  <joint name="base_to_left_wheel" type="continuous">
    <parent link="base_link" />
    <child link="left_wheel_link" />
    <origin xyz="-0.15 0.225 0" rpy="-1.57 0 0" />
    <axis xyz="0 0 1" />
  </joint>

  <link name="left_wheel_link">
    <visual>
      <geometry>
        <cylinder length="0.05" radius="0.1" />
      </geometry>
      <origin xyz="0 0 0" rpy="0 0 0">
      </origin>
      <material name="grey" />
    </visual>
  </link>

  <joint name="base_to_caster_wheel" type="continuous">
    <parent link="base_link" />
    <child link="caster_wheel" />
    <origin xyz="0.2 0 -0.05" rpy="0 0 0" />
    <axis xyz="0 0 1" />
  </joint>

  <link name="caster_wheel">
    <visual>
      <geometry>
        <sphere radius="0.05" />
      </geometry>
      <origin xyz="0 0 0" rpy="0 0 0">
      </origin>
      <material name="blue" />
    </visual>
  </link>

</robot>